Workbook

Sheet Input
A1: Inserire Nome Azienda | C1: Tipologia | D1: Grade | E1: Fido
A2: Inserire ultimo anno disponibile di bilancio | C2: Fornitore
A4: CONTO ECONOMICO
A6: Voce | B6: =$B$2 | C6: =$B$6-1 | D6: =$B$6-2
A7: Valore della Produzione | B7: 0 | C7: 0
A8: Ricavi di vendita | B8: 0 | C8: 0
A9: Costi della Produzione | B9: 0 | C9: 0
A10: Costi per Materie | B10: 0 | C10: 0
A11: Costi per Servizi | B11: 0 | C11: 0
A12: Costi per godimento beni di terzi | B12: 0 | C12: 0
A13: Costi Personale | B13: 0 | C13: 0
A14: Ammortamenti | B14: 0 | C14: 0
A15: Accantonamenti per rischi | B15: 0 | C15: 0
A16: Oneri diversi di gestione | B16: 0 | C16: 0
A17: EBIT | B17: 0 | C17: 0
A18: Proventi Finanziari | B18: 0 | C18: 0
... A21: Dipendenti | B21: 0 | C21: 0
A24: STATO PATRIMONIALE
A26: Voce | B26: =$B$6 | C26: =$C$6 | D26: =$D$6
A27: Immobilizzazioni | B27: 0 | C27: 0
A28: Rimanenze | B28: 0 | C28: 0
A29: Crediti | B29: 0 | C29: 0
A30: Attività Finanziarie | B30: 0 | C30: 0
A31: Disponibilità Liquide | B31: 0 | C31: 0
A32: Ratei e Risconti Attivi | B32: 0 | C32: 0
A33: Totale Attivo | B33: 0 | C33: 0
A34: Totale Patrimonio Netto | B34: 0 | C34: 0
A35: Fondi per rischi e oneri | B35: 0 | C35: 0
A36: Trattamento di fine rapporto di lavoro subordinato | B36: 0 | C36: 0
A37: Totale Debiti | B37: 0 | C37: 0 | E37: =E38+E39 | F37: =F38+F39 | G37: =G38+G39
A38: Debiti esigibili a breve | B38: 0 | C38: 0 | E38: =B38-B41 | F38: =C38-C41 | G38: =D38-D41
A39: Debiti esigibili oltre l’esercizio successivo | B39: 0 | C39: 0 | E39: =B39-B42 | F39: =C39-C42 | G39: =D39-D42
A40: Totale Debiti Finanziari | B40: 0 | C40: 0
A41: Debiti Finanziari esigibili a breve | B41: 0 | C41: 0
A42: Debiti Finanziari esigibili oltre l’esercizio successivo | B42: 0 | C42: 0
A43: Ratei e Risconti Passivi | B43: 0 | C43: 0
A44: Debiti verso fornitori | B44: 0 | C44: 0
A45: Crediti verso clienti | B45: 0 | C45: 0
A46: ATECO 2007
A47: Partita IVA | E47: =IF(LEN(B47)=10,"0"&B47,IF(LEN(B47)=9,"00"&B47,B47))
...

Sheet Report
B1: =Input!B1
A3: Profilo Società
A4: PARTITA IVA | B4: =Input!$E$47
A5: ATECO 2007 | B5: =Input!$B$46 | D5: Fido
A6: FORMA GIURIDICA | B6: =Input!$B$48 | D6: =IF(Input!E2="",Input!$D$85,Input!$E$2)
A7: SEDE | B7: =Input!$B$49
A10: Situazione Reddituale
A11: =IF(B11="Eccellente","nnnnnnnnnnnnn",IF(B11="Positiva","nnnnnnnnnn",IF(B11="Adeguata","nnnnnnn",IF(B11="Critica","nnnn",IF(B11="Molto Critica","n",""))))) | B11: Adeguata | D11: Grade
A13: Situazione Finanziaria
A14: =IF(B14="Eccellente","nnnnnnnnnnnnn",IF(B14="Positiva","nnnnnnnnnn",IF(B14="Adeguata","nnnnnnn",IF(B14="Critica","nnnn",IF(B14="Molto Critica","n",""))))) | B14: =INDEX(Input.$D$118:$H$118,MATCH(Input!C135,Input.$D$119:$H$119,0))
D15: =IF(Input!D2="",Input!$C$83,Input!$D$2)
A16: Situazione Patrimoniale
A17: =IF(B17="Eccellente","nnnnnnnnnnnnn",IF(B17="Positiva","nnnnnnnnnn",IF(B17="Adeguata","nnnnnnn",IF(B17="Critica","nnnn",IF(B17="Molto Critica","n",""))))) | B17: Adeguata
A20: Sintesi KPI | B20: =IF(B98>=1000000,TEXT(TRUNC(B98/1000000,2),"0,00")&" mln",IF(B98>=1000,TEXT(TRUNC(B98/1000,2),"0,00")&"k",TEXT(B98,"0,00")))
A22: Ricavi | B22: EBIT | C22: EBITDA | D22: Utile d'es.
A23: =+Input!B8 | B23: =+Input!B17 | C23: =+Input!B17+Input!B14 | D23: =+Input!B20
A24: =IFERROR(TEXT((Input!B8-Input!C8)/Input!C8,"+0,00%;-0,00%;0,00%") & " vs " & TEXT(Input!C8,"#.##0"),"n.d.") | B24: =IFERROR(TEXT((Input!B17-Input!C17)/Input!C17,"+0,00%;-0,00%;0,00%") & " vs " & TEXT(Input!C17,"#.##0"),"n.d.") | C24: =IFERROR(TEXT(((Input!B17+Input!B14)-(Input!C17+Input!C14))/(Input!C17+Input!C14),"+0,00%;-0,00%;0,00%") & " vs " & TEXT((Input!C17+Input!C14),"#.##0"),"n.d.") | D24: =IFERROR(TEXT((Input!B20-Input!C20)/Input!C20,"+0,00%;-0,00%;0,00%") & " vs " & TEXT(Input!C20,"#.##0"),"n.d.")
A26: Patr. Netto | B26: Deb. Fin. | C26: Disp. Liq. | D26: Dipendenti
A27: =+Input!B34 | B27: =+Input!B40 | C27: =+Input!B31 | D27: =+Input!B21
A28: =IFERROR(TEXT((Input!B34-Input!C34)/Input!C34,"+0,00%;-0,00%;0,00%") & " vs " & TEXT(Input!C34,"#.##0"),"n.d.") | B28: =IFERROR(TEXT((Input!B40-Input!C40)/Input!C40,"+0,00%;-0,00%;0,00%")&" vs "&TEXT(Input!C40,"#.##0"),"n.d.") | C28: =IFERROR(TEXT((Input!B31-Input!C31)/Input!C31,"+0,00%;-0,00%;0,00%") & " vs " & TEXT(Input!C31,"#.##0"),"n.d.") | D28: =IFERROR(TEXT((Input!B21-Input!C21)/Input!C21,"+0,00%;-0,00%;0,00%") & " vs " & TEXT(Input!C21,"#.##0"),"n.d.")
A31: Valutazione
A33: Ambito Economico | C33: Ambito Finanziario e Patrimoniale
A45: Sintesi | C45: Grade e Fido
A58: STATO PATRIMONIALE
A59: Voce | B59: =Input!$B$6 | C59: =Input!$C$6 | D59: Var %
A60: Attivo
A61: Immobilizzazioni | B61: =Input!B27 | C61: =Input!C27 | D61: =IFERROR((B61-C61)/C61,"")
A62: % Immob. su attivo | B62: =B$61/B$73 | C62: =C$61/C$73
A63: Rimanenze | B63: =Input!B28 | C63: =Input!C28 | D63: =IFERROR((B63-C63)/C63,"")
A64: % Rimanenze su attivo | B64: =B$63/B$73 | C64: =C$63/C$73
A65: Crediti | B65: =Input!B29 | C65: =Input!C29 | D65: =IFERROR((B65-C65)/C65,"")
A66: % Crediti su attivo | B66: =B$65/B$73 | C66: =C$65/C$73
A67: Attività Finanziarie | B67: =Input!B30 | C67: =Input!C30 | D67: =IFERROR((B67-C67)/C67,"")
A68: % Attivittà Finanziarie su attivo | B68: =B$67/B$73 | C68: =C$67/C$73
A69: Disponibilità Liquide | B69: =Input!B31 | C69: =Input!C31 | D69: =IFERROR((B69-C69)/C69,"")
A70: % Disp. Liq. su attivo | B70: =B$69/B$73 | C70: =C$69/C$73
A71: Ratei e Risconti Attivi | B71: =Input!B32 | C71: =Input!C32 | D71: =IFERROR((B71-C71)/C71,"")
A72: % Ratei e Risconti attivi su attivo | B72: =B$71/B$73 | C72: =C$71/C$73
A73: Totale Attivo | B73: =Input!B33 | C73: =Input!C33 | D73: =IFERROR((B73-C73)/C73,"")
A75: Passivo
...
